Workbook

Sheet Thailand
A1: No. | B1: LocalName_Thai | C1: Botanical_Name | D1: Family_Name
A2: 1 | B2: เหงือกปลาหมอ | C2: Acanthus ebracteatus Vahl | D2: ACANTHACEAE
A3: 2 | B3: เหงือกปลาหมอ | C3: Acanthus ilicifolius L. | D3: ACANTHACEAE
A4: 3 | B4: หางจระเข้ | C4: Acanthus leucostachyus Wall. ex Nees | D4: ACANTHACEAE
A5: 4 | B5: เหงือกปลาหมอเทศ | C5: Acanthus montanus T.Anderson | D5: ACANTHACEAE
A6: 5 | B6: เหงือกปลาหมอเครือ | C6: Acanthus volubilis Wall. | D6: ACANTHACEAE
A7: 6 | B7: หญ้าบังไพร | C7: Andrographis laxiflora (Blume) Lindau | D7: ACANTHACEAE
A8: 7 | B8: ฟ้าทะลายโจร | C8: Andrographis paniculata (Burm.f.) Wall. ex Nees | D8: ACANTHACEAE
A9: 8 | B9: เอื้องฟ้า | C9: Aphelandra sinclairiana Nees ex Benth. | D9: ACANTHACEAE
A10: 9 | B10: อภิลัญจ์ | C10: Aphelandra squarrosa Nees | D10: ACANTHACEAE
A11: 10 | B11: บาหยา | C11: Asystasia gangetica (L.) T.Anderson subsp. gangetica | D11: ACANTHACEAE
A12: 11 | B12: บาหยา | C12: Asystasia gangetica (L.) T.Anderson subsp. micrantha (Nees) Ensermu | D12: ACANTHACEAE
A13: 12 | B13: เพ็ญทิวา | C13: Asystasia nemorum Nees | D13: ACANTHACEAE
... A9144: 9143 | B9144: หนามกระสุน | C9144: Tribulus terrestris L. | D9144: ZYGOPHYLLACEAE

Sheet VRU
A1: ลำดับ | B1: common_name_th | C1: scientific_name | D1: family
A2: 1 | B2: กรรณิกา | C2: Nyctanthes arbor-tristis L. | D2: OLEACEAE
A3: 2 | B3: กะตังใบ | C3: Leea indica (Burm. f.) Merr. | D3: VITACEAE
A4: 3 | B4: กระถิน | C4: Leucaena leucocephala (Lam.) de Wit | D4: FABACEAE
A5: 4 | B5: กระถินณรงค์ | C5: Acacia auriculiformis A. Cunn. ex Benth. | D5: FABACEAE
A6: 5 | B6: กระดังงาจีน | C6: Artabotrys hexapetalus (L. f.) Bhandari | D6: ANNONACEAE
A7: 6 | B7: กระดังงาสงขลา | C7: Cananga odorata (Lam.) Hook. f. & Thomson var. fruticosa (Craib) J. Sinclair | D7: ANNONACEAE
A8: 7 | B8: กระท้อน | C8: Sandoricum koetjape (Burm. f.) Merr. | D8: MELIACEAE
A9: 8 | B9: กระทิง | C9: Calophyllum inophyllum L. | D9: CALOPHYLLACEAE
A10: 9 | B10: กระทุ่มนา | C10: Mitragyna diversifolia (Wall. ex G. Don) Havil. | D10: RUBIACEAE
A11: 10 | B11: กระพี้จั่น | C11: Millettia brandisiana Kurz | D11: FABACEAE
A12: 11 | B12: กันเกรา | C12: Fagraea fragrans Roxb. | D12: GENTIANACEAE
A13: 12 | B13: กร่าง | C13: Ficus altissima Blume | D13: MORACEAE
... A71: 70 | B71: ไทรย้อยใบแหลม | C71: Ficus benjamina L. | D71: MORACEAE
A72: 71 | B72: ไทรเกาหลี | D72: MORACEAE
A73: 72 | B73: ธรรมรักษา | C73: Heliconia psittacorum L. f. | D73: HELICONIACEAE
A74: 73 | B74: นนทรี | C74: Peltophorum pterocarpum (DC.) Backer ex K. Heyne | D74: FABACEAE
A75: 74 | B75: น้อยหน่า | C75: Annona squamosa L. | D75: ANNONACEAE
A76: 75 | B76: นีออน | C76: Leucophyllum frutescens (Berland.) I. M. Johnst. | D76: SCROPHULARIACEAE
A77: 76 | B77: บานบุรี | C77: Cascabela thevetia (L.) Lippold | D77: APOCYNACEAE
A78: 77 | B78: บุนนาค | C78: Mesua ferrea L. | D78: CALOPHYLLACEAE
A79: 78 | B79: บุหงาส่าหรี | C79: Citharexylum spinosum L. | D79: VERBENACEAE
A80: 79 | B80: บาหยา | C80: Asystasia gangetica (L.) T. Anderson subsp. gangetica | D80: ACANTHACEAE
A81: 80 | B81: ใบเงิน ใบทอง | C81: Graptophyllum pictum (L.) Griff. | D81: ACANTHACEAE
A82: 81 | B82: ปรงญี่ปุ่น | C82: Cycas revoluta Thunb. | D82: CYCADACEAE
A83: 82 | B83: ประยงค์ | C83: Aglaia odorata Lour. | D83: MELIACEAE
A84: 83 | B84: ประดู่บ้าน | C84: Pterocarpus indicus Willd. | D84: FABACEAE
... A193: 192 | B193: เฮลิโคเนีย | C193: Heliconia rostrata Ruiz. & Pav. | D193: HELICONIACEAE

Sheet DATABASE
A1: id | B1: species_name | C1: slug | D1: common_name | E1: common_name_th | F1: genus | G1: family | H1: scientific_name | I1: description
A2: 1 | B2: ebracteatus | C2: acanthus-ebracteatus | D2: Acanthus ebracteatus | E2: =IFERROR(INDEX(Thailand!B$2:B$9144,ROW(A1)),"") -> เหงือกปลาหมอ | F2: Acanthus | G2: =IFERROR(INDEX(Thailand!D$2:D$9144,ROW(A1)),"") -> ACANTHACEAE | H2: =IFERROR(INDEX(Thailand!C$2:C$9144,ROW(A1)),"") -> Acanthus ebracteatus Vahl | I2: เหงือกปลาหมอ (ชื่อวิทยาศาสตร์: Acanthus ebracteatus) เป็นพืชในวงศ์ ACANTHACEAE ซึ่งพบกระจายพันธุ์ในหลายภูมิภาคของโลก โดยเฉพาะในเขตร้อนและกึ่งเขตร้อน พืชในสกุล Acanthus มักมีลักษณะเป็นไม้ล้มลุก ไม้พุ่ม หรือไม้ยืนต้น ขึ้นอยู่กับชนิด มีลักษณะทางกายภาพที่แตกต่างกัน เช่น รูปทรงของใบที่อาจเป็นรูปรี รูปหอก หรือรูปไข่ และมีดอกที่มีสีสันหรือรูปแบบเฉพาะตัวซึ่งช่วยในการจำแนกชนิด พืชชนิดนี้มักพบในแหล่งที่อยู่อาศัยตามธรรมชาติ เช่น ป่า ทุ่งหญ้า พื้นที่ชุ่มน้ำ หรือพื้นที่ชายฝั่ง และมีบทบาทสำคัญในระบบนิเวศ เช่น เป็นแหล่งอาหารของสัตว์และช่วยรักษาสมดุลของสิ่งแวดล้อม นอกจากนี้ยังมีการนำมาใช้ประโยชน์ในด้านต่าง ๆ เช่น การใช้เป็นไม้ประดับ การใช้ในทางสมุนไพร การใช้เป็นแหล่งอาหาร หรือการใช้ในงานวิจัยทางพฤกษศาสตร์และนิเวศวิทยา พืชชนิดนี้มีความสำคัญทั้งในด้านความหลากหลายทางชีวภาพและการใช้ประโยชน์ของมนุษย์ในหลายภูมิภาคทั่วโลก.
A3: 2 | B3: ilicifolius | C3: acanthus-ilicifolius | D3: Acanthus ilicifolius | E3: =IFERROR(INDEX(Thailand!B$2:B$9144,ROW(A2)),"") -> เหงือกปลาหมอ | F3: Acanthus | G3: =IFERROR(INDEX(Thailand!D$2:D$9144,ROW(A2)),"") -> ACANTHACEAE | H3: =IFERROR(INDEX(Thailand!C$2:C$9144,ROW(A2)),"") -> Acanthus ilicifolius L. | I3: เหงือกปลาหมอ (ชื่อวิทยาศาสตร์: Acanthus ilicifolius) เป็นพืชในวงศ์ ACANTHACEAE ซึ่งพบกระจายพันธุ์ในหลายภูมิภาคของโลก โดยเฉพาะในเขตร้อนและกึ่งเขตร้อน พืชในสกุล Acanthus มักมีลักษณะเป็นไม้ล้มลุก ไม้พุ่ม หรือไม้ยืนต้น ขึ้นอยู่กับชนิด มีลักษณะทางกายภาพที่แตกต่างกัน เช่น รูปทรงของใบที่อาจเป็นรูปรี รูปหอก หรือรูปไข่ และมีดอกที่มีสีสันหรือรูปแบบเฉพาะตัวซึ่งช่วยในการจำแนกชนิด พืชชนิดนี้มักพบในแหล่งที่อยู่อาศัยตามธรรมชาติ เช่น ป่า ทุ่งหญ้า พื้นที่ชุ่มน้ำ หรือพื้นที่ชายฝั่ง และมีบทบาทสำคัญในระบบนิเวศ เช่น เป็นแหล่งอาหารของสัตว์และช่วยรักษาสมดุลของสิ่งแวดล้อม นอกจากนี้ยังมีการนำมาใช้ประโยชน์ในด้านต่าง ๆ เช่น การใช้เป็นไม้ประดับ การใช้ในทางสมุนไพร การใช้เป็นแหล่งอาหาร หรือการใช้ในงานวิจัยทางพฤกษศาสตร์และนิเวศวิทยา พืชชนิดนี้มีความสำคัญทั้งในด้านความหลากหลายทางชีวภาพและการใช้ประโยชน์ของมนุษย์ในหลายภูมิภาคทั่วโลก.
A4: 3 | B4: leucostachyus | C4: acanthus-leucostachyus | D4: Acanthus leucostachyus | E4: =IFERROR(INDEX(Thailand!B$2:B$9144,ROW(A3)),"") -> หางจระเข้ | F4: Acanthus | G4: =IFERROR(INDEX(Thailand!D$2:D$9144,ROW(A3)),"") -> ACANTHACEAE | H4: =IFERROR(INDEX(Thailand!C$2:C$9144,ROW(A3)),"") -> Acanthus leucostachyus Wall. ex Nees | I4: หางจระเข้ (ชื่อวิทยาศาสตร์: Acanthus leucostachyus) เป็นพืชในวงศ์ ACANTHACEAE ซึ่งพบกระจายพันธุ์ในหลายภูมิภาคของโลก โดยเฉพาะในเขตร้อนและกึ่งเขตร้อน พืชในสกุล Acanthus มักมีลักษณะเป็นไม้ล้มลุก ไม้พุ่ม หรือไม้ยืนต้น ขึ้นอยู่กับชนิด มีลักษณะทางกายภาพที่แตกต่างกัน เช่น รูปทรงของใบที่อาจเป็นรูปรี รูปหอก หรือรูปไข่ และมีดอกที่มีสีสันหรือรูปแบบเฉพาะตัวซึ่งช่วยในการจำแนกชนิด พืชชนิดนี้มักพบในแหล่งที่อยู่อาศัยตามธรรมชาติ เช่น ป่า ทุ่งหญ้า พื้นที่ชุ่มน้ำ หรือพื้นที่ชายฝั่ง และมีบทบาทสำคัญในระบบนิเวศ เช่น เป็นแหล่งอาหารของสัตว์และช่วยรักษาสมดุลของสิ่งแวดล้อม นอกจากนี้ยังมีการนำมาใช้ประโยชน์ในด้านต่าง ๆ เช่น การใช้เป็นไม้ประดับ การใช้ในทางสมุนไพร การใช้เป็นแหล่งอาหาร หรือการใช้ในงานวิจัยทางพฤกษศาสตร์และนิเวศวิทยา พืชชนิดนี้มีความสำคัญทั้งในด้านความหลากหลายทางชีวภาพและการใช้ประโยชน์ของมนุษย์ในหลายภูมิภาคทั่วโลก.
A5: 4 | B5: montanus | C5: acanthus-montanus | D5: Acanthus montanus | E5: =IFERROR(INDEX(Thailand!B$2:B$9144,ROW(A4)),"") -> เหงือกปลาหมอเทศ | F5: Acanthus | G5: =IFERROR(INDEX(Thailand!D$2:D$9144,ROW(A4)),"") -> ACANTHACEAE | H5: =IFERROR(INDEX(Thailand!C$2:C$9144,ROW(A4)),"") -> Acanthus montanus T.Anderson | I5: เหงือกปลาหมอเทศ (ชื่อวิทยาศาสตร์: Acanthus montanus) เป็นพืชในวงศ์ ACANTHACEAE ซึ่งพบกระจายพันธุ์ในหลายภูมิภาคของโลก โดยเฉพาะในเขตร้อนและกึ่งเขตร้อน พืชในสกุล Acanthus มักมีลักษณะเป็นไม้ล้มลุก ไม้พุ่ม หรือไม้ยืนต้น ขึ้นอยู่กับชนิด มีลักษณะทางกายภาพที่แตกต่างกัน เช่น รูปทรงของใบที่อาจเป็นรูปรี รูปหอก หรือรูปไข่ และมีดอกที่มีสีสันหรือรูปแบบเฉพาะตัวซึ่งช่วยในการจำแนกชนิด พืชชนิดนี้มักพบในแหล่งที่อยู่อาศัยตามธรรมชาติ เช่น ป่า ทุ่งหญ้า พื้นที่ชุ่มน้ำ หรือพื้นที่ชายฝั่ง และมีบทบาทสำคัญในระบบนิเวศ เช่น เป็นแหล่งอาหารของสัตว์และช่วยรักษาสมดุลของสิ่งแวดล้อม นอกจากนี้ยังมีการนำมาใช้ประโยชน์ในด้านต่าง ๆ เช่น การใช้เป็นไม้ประดับ การใช้ในทางสมุนไพร การใช้เป็นแหล่งอาหาร หรือการใช้ในงานวิจัยทางพฤกษศาสตร์และนิเวศวิทยา พืชชนิดนี้มีความสำคัญทั้งในด้านความหลากหลายทางชีวภาพและการใช้ประโยชน์ของมนุษย์ในหลายภูมิภาคทั่วโลก.
A6: 5 | B6: volubilis | C6: acanthus-volubilis | D6: Acanthus volubilis | E6: =IFERROR(INDEX(Thailand!B$2:B$9144,ROW(A5)),"") -> เหงือกปลาหมอเครือ | F6: Acanthus | G6: =IFERROR(INDEX(Thailand!D$2:D$9144,ROW(A5)),"") -> ACANTHACEAE | H6: =IFERROR(INDEX(Thailand!C$2:C$9144,ROW(A5)),"") -> Acanthus volubilis Wall. | I6: เหงือกปลาหมอเครือ (ชื่อวิทยาศาสตร์: Acanthus volubilis) เป็นพืชในวงศ์ ACANTHACEAE ซึ่งพบกระจายพันธุ์ในหลายภูมิภาคของโลก โดยเฉพาะในเขตร้อนและกึ่งเขตร้อน พืชในสกุล Acanthus มักมีลักษณะเป็นไม้ล้มลุก ไม้พุ่ม หรือไม้ยืนต้น ขึ้นอยู่กับชนิด มีลักษณะทางกายภาพที่แตกต่างกัน เช่น รูปทรงของใบที่อาจเป็นรูปรี รูปหอก หรือรูปไข่ และมีดอกที่มีสีสันหรือรูปแบบเฉพาะตัวซึ่งช่วยในการจำแนกชนิด พืชชนิดนี้มักพบในแหล่งที่อยู่อาศัยตามธรรมชาติ เช่น ป่า ทุ่งหญ้า พื้นที่ชุ่มน้ำ หรือพื้นที่ชายฝั่ง และมีบทบาทสำคัญในระบบนิเวศ เช่น เป็นแหล่งอาหารของสัตว์และช่วยรักษาสมดุลของสิ่งแวดล้อม นอกจากนี้ยังมีการนำมาใช้ประโยชน์ในด้านต่าง ๆ เช่น การใช้เป็นไม้ประดับ การใช้ในทางสมุนไพร การใช้เป็นแหล่งอาหาร หรือการใช้ในงานวิจัยทางพฤกษศาสตร์และนิเวศวิทยา พืชชนิดนี้มีความสำคัญทั้งในด้านความหลากหลายทางชีวภาพและการใช้ประโยชน์ของมนุษย์ในหลายภูมิภาคทั่วโลก.
A7: 6 | B7: laxiflora | C7: andrographis-laxiflora | D7: Andrographis laxiflora | E7: =IFERROR(INDEX(Thailand!B$2:B$9144,ROW(A6)),"") -> หญ้าบังไพร | F7: Andrographis | G7: =IFERROR(INDEX(Thailand!D$2:D$9144,ROW(A6)),"") -> ACANTHACEAE | H7: =IFERROR(INDEX(Thailand!C$2:C$9144,ROW(A6)),"") -> Andrographis laxiflora (Blume) Lindau | I7: หญ้าบังไพร (ชื่อวิทยาศาสตร์: Andrographis laxiflora) เป็นพืชในวงศ์ ACANTHACEAE ซึ่งพบกระจายพันธุ์ในหลายภูมิภาคของโลก โดยเฉพาะในเขตร้อนและกึ่งเขตร้อน พืชในสกุล Andrographis มักมีลักษณะเป็นไม้ล้มลุก ไม้พุ่ม หรือไม้ยืนต้น ขึ้นอยู่กับชนิด มีลักษณะทางกายภาพที่แตกต่างกัน เช่น รูปทรงของใบที่อาจเป็นรูปรี รูปหอก หรือรูปไข่ และมีดอกที่มีสีสันหรือรูปแบบเฉพาะตัวซึ่งช่วยในการจำแนกชนิด พืชชนิดนี้มักพบในแหล่งที่อยู่อาศัยตามธรรมชาติ เช่น ป่า ทุ่งหญ้า พื้นที่ชุ่มน้ำ หรือพื้นที่ชายฝั่ง และมีบทบาทสำคัญในระบบนิเวศ เช่น เป็นแหล่งอาหารของสัตว์และช่วยรักษาสมดุลของสิ่งแวดล้อม นอกจากนี้ยังมีการนำมาใช้ประโยชน์ในด้านต่าง ๆ เช่น การใช้เป็นไม้ประดับ การใช้ในทางสมุนไพร การใช้เป็นแหล่งอาหาร หรือการใช้ในงานวิจัยทางพฤกษศาสตร์และนิเวศวิทยา พืชชนิดนี้มีความสำคัญทั้งในด้านความหลากหลายทางชีวภาพและการใช้ประโยชน์ของมนุษย์ในหลายภูมิภาคทั่วโลก.
A8: 7 | B8: paniculata | C8: andrographis-paniculata | D8: Andrographis paniculata | E8: =IFERROR(INDEX(Thailand!B$2:B$9144,ROW(A7)),"") -> ฟ้าทะลายโจร | F8: Andrographis | G8: =IFERROR(INDEX(Thailand!D$2:D$9144,ROW(A7)),"") -> ACANTHACEAE | H8: =IFERROR(INDEX(Thailand!C$2:C$9144,ROW(A7)),"") -> Andrographis paniculata (Burm.f.) Wall. ex Nees | I8: ฟ้าทะลายโจร (ชื่อวิทยาศาสตร์: Andrographis paniculata) เป็นพืชในวงศ์ ACANTHACEAE ซึ่งพบกระจายพันธุ์ในหลายภูมิภาคของโลก โดยเฉพาะในเขตร้อนและกึ่งเขตร้อน พืชในสกุล Andrographis มักมีลักษณะเป็นไม้ล้มลุก ไม้พุ่ม หรือไม้ยืนต้น ขึ้นอยู่กับชนิด มีลักษณะทางกายภาพที่แตกต่างกัน เช่น รูปทรงของใบที่อาจเป็นรูปรี รูปหอก หรือรูปไข่ และมีดอกที่มีสีสันหรือรูปแบบเฉพาะตัวซึ่งช่วยในการจำแนกชนิด พืชชนิดนี้มักพบในแหล่งที่อยู่อาศัยตามธรรมชาติ เช่น ป่า ทุ่งหญ้า พื้นที่ชุ่มน้ำ หรือพื้นที่ชายฝั่ง และมีบทบาทสำคัญในระบบนิเวศ เช่น เป็นแหล่งอาหารของสัตว์และช่วยรักษาสมดุลของสิ่งแวดล้อม นอกจากนี้ยังมีการนำมาใช้ประโยชน์ในด้านต่าง ๆ เช่น การใช้เป็นไม้ประดับ การใช้ในทางสมุนไพร การใช้เป็นแหล่งอาหาร หรือการใช้ในงานวิจัยทางพฤกษศาสตร์และนิเวศวิทยา พืชชนิดนี้มีความสำคัญทั้งในด้านความหลากหลายทางชีวภาพและการใช้ประโยชน์ของมนุษย์ในหลายภูมิภาคทั่วโลก.
A9: 8 | B9: sinclairiana | C9: aphelandra-sinclairiana | D9: Aphelandra sinclairiana | E9: =IFERROR(INDEX(Thailand!B$2:B$9144,ROW(A8)),"") -> เอื้องฟ้า | F9: Aphelandra | G9: =IFERROR(INDEX(Thailand!D$2:D$9144,ROW(A8)),"") -> ACANTHACEAE | H9: =IFERROR(INDEX(Thailand!C$2:C$9144,ROW(A8)),"") -> Aphelandra sinclairiana Nees ex Benth. | I9: เอื้องฟ้า (ชื่อวิทยาศาสตร์: Aphelandra sinclairiana) เป็นพืชในวงศ์ ACANTHACEAE ซึ่งพบกระจายพันธุ์ในหลายภูมิภาคของโลก โดยเฉพาะในเขตร้อนและกึ่งเขตร้อน พืชในสกุล Aphelandra มักมีลักษณะเป็นไม้ล้มลุก ไม้พุ่ม หรือไม้ยืนต้น ขึ้นอยู่กับชนิด มีลักษณะทางกายภาพที่แตกต่างกัน เช่น รูปทรงของใบที่อาจเป็นรูปรี รูปหอก หรือรูปไข่ และมีดอกที่มีสีสันหรือรูปแบบเฉพาะตัวซึ่งช่วยในการจำแนกชนิด พืชชนิดนี้มักพบในแหล่งที่อยู่อาศัยตามธรรมชาติ เช่น ป่า ทุ่งหญ้า พื้นที่ชุ่มน้ำ หรือพื้นที่ชายฝั่ง และมีบทบาทสำคัญในระบบนิเวศ เช่น เป็นแหล่งอาหารของสัตว์และช่วยรักษาสมดุลของสิ่งแวดล้อม นอกจากนี้ยังมีการนำมาใช้ประโยชน์ในด้านต่าง ๆ เช่น การใช้เป็นไม้ประดับ การใช้ในทางสมุนไพร การใช้เป็นแหล่งอาหาร หรือการใช้ในงานวิจัยทางพฤกษศาสตร์และนิเวศวิทยา พืชชนิดนี้มีความสำคัญทั้งในด้านความหลากหลายทางชีวภาพและการใช้ประโยชน์ของมนุษย์ในหลายภูมิภาคทั่วโลก.
A10: 9 | B10: squarrosa | C10: aphelandra-squarrosa | D10: Aphelandra squarrosa | E10: =IFERROR(INDEX(Thailand!B$2:B$9144,ROW(A9)),"") -> อภิลัญจ์ | F10: Aphelandra | G10: =IFERROR(INDEX(Thailand!D$2:D$9144,ROW(A9)),"") -> ACANTHACEAE | H10: =IFERROR(INDEX(Thailand!C$2:C$9144,ROW(A9)),"") -> Aphelandra squarrosa Nees | I10: อภิลัญจ์ (ชื่อวิทยาศาสตร์: Aphelandra squarrosa) เป็นพืชในวงศ์ ACANTHACEAE ซึ่งพบกระจายพันธุ์ในหลายภูมิภาคของโลก โดยเฉพาะในเขตร้อนและกึ่งเขตร้อน พืชในสกุล Aphelandra มักมีลักษณะเป็นไม้ล้มลุก ไม้พุ่ม หรือไม้ยืนต้น ขึ้นอยู่กับชนิด มีลักษณะทางกายภาพที่แตกต่างกัน เช่น รูปทรงของใบที่อาจเป็นรูปรี รูปหอก หรือรูปไข่ และมีดอกที่มีสีสันหรือรูปแบบเฉพาะตัวซึ่งช่วยในการจำแนกชนิด พืชชนิดนี้มักพบในแหล่งที่อยู่อาศัยตามธรรมชาติ เช่น ป่า ทุ่งหญ้า พื้นที่ชุ่มน้ำ หรือพื้นที่ชายฝั่ง และมีบทบาทสำคัญในระบบนิเวศ เช่น เป็นแหล่งอาหารของสัตว์และช่วยรักษาสมดุลของสิ่งแวดล้อม นอกจากนี้ยังมีการนำมาใช้ประโยชน์ในด้านต่าง ๆ เช่น การใช้เป็นไม้ประดับ การใช้ในทางสมุนไพร การใช้เป็นแหล่งอาหาร หรือการใช้ในงานวิจัยทางพฤกษศาสตร์และนิเวศวิทยา พืชชนิดนี้มีความสำคัญทั้งในด้านความหลากหลายทางชีวภาพและการใช้ประโยชน์ของมนุษย์ในหลายภูมิภาคทั่วโลก.
A11: 10 | B11: gangetica | C11: asystasia-gangetica | D11: Asystasia gangetica | E11: =IFERROR(INDEX(Thailand!B$2:B$9144,ROW(A10)),"") -> บาหยา | F11: Asystasia | G11: =IFERROR(INDEX(Thailand!D$2:D$9144,ROW(A10)),"") -> ACANTHACEAE | H11: =IFERROR(INDEX(Thailand!C$2:C$9144,ROW(A10)),"") -> Asystasia gangetica (L.) T.Anderson subsp. gangetica | I11: บาหยา (ชื่อวิทยาศาสตร์: Asystasia gangetica) เป็นพืชในวงศ์ ACANTHACEAE ซึ่งพบกระจายพันธุ์ในหลายภูมิภาคของโลก โดยเฉพาะในเขตร้อนและกึ่งเขตร้อน พืชในสกุล Asystasia มักมีลักษณะเป็นไม้ล้มลุก ไม้พุ่ม หรือไม้ยืนต้น ขึ้นอยู่กับชนิด มีลักษณะทางกายภาพที่แตกต่างกัน เช่น รูปทรงของใบที่อาจเป็นรูปรี รูปหอก หรือรูปไข่ และมีดอกที่มีสีสันหรือรูปแบบเฉพาะตัวซึ่งช่วยในการจำแนกชนิด พืชชนิดนี้มักพบในแหล่งที่อยู่อาศัยตามธรรมชาติ เช่น ป่า ทุ่งหญ้า พื้นที่ชุ่มน้ำ หรือพื้นที่ชายฝั่ง และมีบทบาทสำคัญในระบบนิเวศ เช่น เป็นแหล่งอาหารของสัตว์และช่วยรักษาสมดุลของสิ่งแวดล้อม นอกจากนี้ยังมีการนำมาใช้ประโยชน์ในด้านต่าง ๆ เช่น การใช้เป็นไม้ประดับ การใช้ในทางสมุนไพร การใช้เป็นแหล่งอาหาร หรือการใช้ในงานวิจัยทางพฤกษศาสตร์และนิเวศวิทยา พืชชนิดนี้มีความสำคัญทั้งในด้านความหลากหลายทางชีวภาพและการใช้ประโยชน์ของมนุษย์ในหลายภูมิภาคทั่วโลก.
A12: 11 | B12: gangetica | C12: asystasia-gangetica | D12: Asystasia gangetica | E12: =IFERROR(INDEX(Thailand!B$2:B$9144,ROW(A11)),"") -> บาหยา | F12: Asystasia | G12: =IFERROR(INDEX(Thailand!D$2:D$9144,ROW(A11)),"") -> ACANTHACEAE | H12: =IFERROR(INDEX(Thailand!C$2:C$9144,ROW(A11)),"") -> Asystasia gangetica (L.) T.Anderson subsp. micrantha (Nees) Ensermu | I12: บาหยา (ชื่อวิทยาศาสตร์: Asystasia gangetica) เป็นพืชในวงศ์ ACANTHACEAE ซึ่งพบกระจายพันธุ์ในหลายภูมิภาคของโลก โดยเฉพาะในเขตร้อนและกึ่งเขตร้อน พืชในสกุล Asystasia มักมีลักษณะเป็นไม้ล้มลุก ไม้พุ่ม หรือไม้ยืนต้น ขึ้นอยู่กับชนิด มีลักษณะทางกายภาพที่แตกต่างกัน เช่น รูปทรงของใบที่อาจเป็นรูปรี รูปหอก หรือรูปไข่ และมีดอกที่มีสีสันหรือรูปแบบเฉพาะตัวซึ่งช่วยในการจำแนกชนิด พืชชนิดนี้มักพบในแหล่งที่อยู่อาศัยตามธรรมชาติ เช่น ป่า ทุ่งหญ้า พื้นที่ชุ่มน้ำ หรือพื้นที่ชายฝั่ง และมีบทบาทสำคัญในระบบนิเวศ เช่น เป็นแหล่งอาหารของสัตว์และช่วยรักษาสมดุลของสิ่งแวดล้อม นอกจากนี้ยังมีการนำมาใช้ประโยชน์ในด้านต่าง ๆ เช่น การใช้เป็นไม้ประดับ การใช้ในทางสมุนไพร การใช้เป็นแหล่งอาหาร หรือการใช้ในงานวิจัยทางพฤกษศาสตร์และนิเวศวิทยา พืชชนิดนี้มีความสำคัญทั้งในด้านความหลากหลายทางชีวภาพและการใช้ประโยชน์ของมนุษย์ในหลายภูมิภาคทั่วโลก.
A13: 12 | B13: nemorum | C13: asystasia-nemorum | D13: Asystasia nemorum | E13: =IFERROR(INDEX(Thailand!B$2:B$9144,ROW(A12)),"") -> เพ็ญทิวา | F13: Asystasia | G13: =IFERROR(INDEX(Thailand!D$2:D$9144,ROW(A12)),"") -> ACANTHACEAE | H13: =IFERROR(INDEX(Thailand!C$2:C$9144,ROW(A12)),"") -> Asystasia nemorum Nees | I13: เพ็ญทิวา (ชื่อวิทยาศาสตร์: Asystasia nemorum) เป็นพืชในวงศ์ ACANTHACEAE ซึ่งพบกระจายพันธุ์ในหลายภูมิภาคของโลก โดยเฉพาะในเขตร้อนและกึ่งเขตร้อน พืชในสกุล Asystasia มักมีลักษณะเป็นไม้ล้มลุก ไม้พุ่ม หรือไม้ยืนต้น ขึ้นอยู่กับชนิด มีลักษณะทางกายภาพที่แตกต่างกัน เช่น รูปทรงของใบที่อาจเป็นรูปรี รูปหอก หรือรูปไข่ และมีดอกที่มีสีสันหรือรูปแบบเฉพาะตัวซึ่งช่วยในการจำแนกชนิด พืชชนิดนี้มักพบในแหล่งที่อยู่อาศัยตามธรรมชาติ เช่น ป่า ทุ่งหญ้า พื้นที่ชุ่มน้ำ หรือพื้นที่ชายฝั่ง และมีบทบาทสำคัญในระบบนิเวศ เช่น เป็นแหล่งอาหารของสัตว์และช่วยรักษาสมดุลของสิ่งแวดล้อม นอกจากนี้ยังมีการนำมาใช้ประโยชน์ในด้านต่าง ๆ เช่น การใช้เป็นไม้ประดับ การใช้ในทางสมุนไพร การใช้เป็นแหล่งอาหาร หรือการใช้ในงานวิจัยทางพฤกษศาสตร์และนิเวศวิทยา พืชชนิดนี้มีความสำคัญทั้งในด้านความหลากหลายทางชีวภาพและการใช้ประโยชน์ของมนุษย์ในหลายภูมิภาคทั่วโลก.
... A9144: 9143 | B9144: terrestris | C9144: tribulus-terrestris | D9144: Tribulus terrestris | E9144: =IFERROR(INDEX(Thailand!B$2:B$9144,ROW(A9143)),"") -> หนามกระสุน | F9144: Tribulus | G9144: =IFERROR(INDEX(Thailand!D$2:D$9144,ROW(A9143)),"") -> ZYGOPHYLLACEAE | H9144: =IFERROR(INDEX(Thailand!C$2:C$9144,ROW(A9143)),"") -> Tribulus terrestris L. | I9144: หนามกระสุน (ชื่อวิทยาศาสตร์: Tribulus terrestris) เป็นพืชในวงศ์ ZYGOPHYLLACEAE ซึ่งพบกระจายพันธุ์ในหลายภูมิภาคทั่วโลก โดยเฉพาะในเขตร้อนและกึ่งเขตร้อน มีลักษณะเป็นไม้ล้มลุก ไม้พุ่ม หรือไม้ยืนต้น ใบมีรูปร่างหลากหลาย เช่น รูปรี รูปไข่ หรือรูปหอก และมีดอกที่มีโครงสร้างเฉพาะตัว พืชชนิดนี้พบในแหล่งธรรมชาติ เช่น ป่าเขตร้อน ทุ่งหญ้า พื้นที่ชุ่มน้ำ หรือพื้นที่ชายฝั่ง มีบทบาทสำคัญในระบบนิเวศ เช่น เป็นแหล่งอาหารของสัตว์และช่วยรักษาสมดุลของสิ่งแวดล้อม นอกจากนี้ยังมีการใช้ประโยชน์ในด้านต่าง ๆ เช่น การใช้เป็นไม้ประดับ การใช้ในทางสมุนไพร การใช้เป็นอาหาร และการใช้ในการศึกษาทางวิทยาศาสตร์และพฤกษศาสตร์.
A9145: 9144 | B9145: arbor-tristis | C9145: nyctanthes-arbor-tristis | D9145: Nyctanthes arbor-tristis | E9145: {=IFERROR(INDEX(VRU!B$2:B$194,SMALL(IF(COUNTIF(Thailand!B$2:B$9145,VRU!B$2:B$194)=0,ROW(VRU!B$2:B$194)-ROW(VRU!B$2)+1),ROW(A1))),"")} -> กรรณิกา | F9145: Nyctanthes | G9145: =IFERROR(INDEX(VRU!D$2:D$194,MATCH(E9145,VRU!B$2:B$194,0)),"") -> OLEACEAE | H9145: =IFERROR(INDEX(VRU!C$2:C$194,MATCH(E9145,VRU!B$2:B$194,0)),"") -> Nyctanthes arbor-tristis L. | I9145: กรรณิกา (ชื่อวิทยาศาสตร์: Nyctanthes arbor-tristis) เป็นพืชในวงศ์ OLEACEAE ซึ่งพบกระจายพันธุ์ในหลายภูมิภาคทั่วโลก โดยเฉพาะในเขตร้อนและกึ่งเขตร้อน มีลักษณะเป็นไม้ล้มลุก ไม้พุ่ม หรือไม้ยืนต้น ใบมีรูปร่างหลากหลาย เช่น รูปรี รูปไข่ หรือรูปหอก และมีดอกที่มีโครงสร้างเฉพาะตัว พืชชนิดนี้พบในแหล่งธรรมชาติ เช่น ป่าเขตร้อน ทุ่งหญ้า พื้นที่ชุ่มน้ำ หรือพื้นที่ชายฝั่ง มีบทบาทสำคัญในระบบนิเวศ เช่น เป็นแหล่งอาหารของสัตว์และช่วยรักษาสมดุลของสิ่งแวดล้อม นอกจากนี้ยังมีการใช้ประโยชน์ในด้านต่าง ๆ เช่น การใช้เป็นไม้ประดับ การใช้ในทางสมุนไพร การใช้เป็นอาหาร และการใช้ในการศึกษาทางวิทยาศาสตร์และพฤกษศาสตร์.
A9146: 9145 | B9146: sp. | C9146: musa-sp. | D9146: Musa sp. | E9146: {=IFERROR(INDEX(VRU!B$2:B$194,SMALL(IF(COUNTIF(Thailand!B$2:B$9145,VRU!B$2:B$194)=0,ROW(VRU!B$2:B$194)-ROW(VRU!B$2)+1),ROW(A2))),"")} -> กล้วย | F9146: Musa | G9146: =IFERROR(INDEX(VRU!D$2:D$194,MATCH(E9146,VRU!B$2:B$194,0)),"") -> MUSACEAE | H9146: =IFERROR(INDEX(VRU!C$2:C$194,MATCH(E9146,VRU!B$2:B$194,0)),"") -> Musa sp. | I9146: กล้วย (ชื่อวิทยาศาสตร์: Musa sp.) เป็นพืชในวงศ์ MUSACEAE ซึ่งพบกระจายพันธุ์ในหลายภูมิภาคทั่วโลก โดยเฉพาะในเขตร้อนและกึ่งเขตร้อน มีลักษณะเป็นไม้ล้มลุก ไม้พุ่ม หรือไม้ยืนต้น ใบมีรูปร่างหลากหลาย เช่น รูปรี รูปไข่ หรือรูปหอก และมีดอกที่มีโครงสร้างเฉพาะตัว พืชชนิดนี้พบในแหล่งธรรมชาติ เช่น ป่าเขตร้อน ทุ่งหญ้า พื้นที่ชุ่มน้ำ หรือพื้นที่ชายฝั่ง มีบทบาทสำคัญในระบบนิเวศ เช่น เป็นแหล่งอาหารของสัตว์และช่วยรักษาสมดุลของสิ่งแวดล้อม นอกจากนี้ยังมีการใช้ประโยชน์ในด้านต่าง ๆ เช่น การใช้เป็นไม้ประดับ การใช้ในทางสมุนไพร การใช้เป็นอาหาร และการใช้ในการศึกษาทางวิทยาศาสตร์และพฤกษศาสตร์.
A9147: 9146 | B9147: trifolia | C9147: vitex-trifolia | D9147: Vitex trifolia | E9147: {=IFERROR(INDEX(VRU!B$2:B$194,SMALL(IF(COUNTIF(Thailand!B$2:B$9145,VRU!B$2:B$194)=0,ROW(VRU!B$2:B$194)-ROW(VRU!B$2)+1),ROW(A3))),"")} -> คนทีสอ | F9147: Vitex | G9147: =IFERROR(INDEX(VRU!D$2:D$194,MATCH(E9147,VRU!B$2:B$194,0)),"") -> LAMIACEAE | H9147: =IFERROR(INDEX(VRU!C$2:C$194,MATCH(E9147,VRU!B$2:B$194,0)),"") -> Vitex trifolia L. subsp. trifolia | I9147: คนทีสอ (ชื่อวิทยาศาสตร์: Vitex trifolia) เป็นพืชในวงศ์ LAMIACEAE ซึ่งพบกระจายพันธุ์ในหลายภูมิภาคทั่วโลก โดยเฉพาะในเขตร้อนและกึ่งเขตร้อน มีลักษณะเป็นไม้ล้มลุก ไม้พุ่ม หรือไม้ยืนต้น ใบมีรูปร่างหลากหลาย เช่น รูปรี รูปไข่ หรือรูปหอก และมีดอกที่มีโครงสร้างเฉพาะตัว พืชชนิดนี้พบในแหล่งธรรมชาติ เช่น ป่าเขตร้อน ทุ่งหญ้า พื้นที่ชุ่มน้ำ หรือพื้นที่ชายฝั่ง มีบทบาทสำคัญในระบบนิเวศ เช่น เป็นแหล่งอาหารของสัตว์และช่วยรักษาสมดุลของสิ่งแวดล้อม นอกจากนี้ยังมีการใช้ประโยชน์ในด้านต่าง ๆ เช่น การใช้เป็นไม้ประดับ การใช้ในทางสมุนไพร การใช้เป็นอาหาร และการใช้ในการศึกษาทางวิทยาศาสตร์และพฤกษศาสตร์.
A9148: 9147 | B9148: horridus | C9148: oxyceros-horridus | D9148: Oxyceros horridus | E9148: {=IFERROR(INDEX(VRU!B$2:B$194,SMALL(IF(COUNTIF(Thailand!B$2:B$9145,VRU!B$2:B$194)=0,ROW(VRU!B$2:B$194)-ROW(VRU!B$2)+1),ROW(A4))),"")} -> คัดเค้า | F9148: Oxyceros | G9148: =IFERROR(INDEX(VRU!D$2:D$194,MATCH(E9148,VRU!B$2:B$194,0)),"") -> RUBIACEAE | H9148: =IFERROR(INDEX(VRU!C$2:C$194,MATCH(E9148,VRU!B$2:B$194,0)),"") -> Oxyceros horridus Lour. | I9148: คัดเค้า (ชื่อวิทยาศาสตร์: Oxyceros horridus) เป็นพืชในวงศ์ RUBIACEAE ซึ่งพบกระจายพันธุ์ในหลายภูมิภาคทั่วโลก โดยเฉพาะในเขตร้อนและกึ่งเขตร้อน มีลักษณะเป็นไม้ล้มลุก ไม้พุ่ม หรือไม้ยืนต้น ใบมีรูปร่างหลากหลาย เช่น รูปรี รูปไข่ หรือรูปหอก และมีดอกที่มีโครงสร้างเฉพาะตัว พืชชนิดนี้พบในแหล่งธรรมชาติ เช่น ป่าเขตร้อน ทุ่งหญ้า พื้นที่ชุ่มน้ำ หรือพื้นที่ชายฝั่ง มีบทบาทสำคัญในระบบนิเวศ เช่น เป็นแหล่งอาหารของสัตว์และช่วยรักษาสมดุลของสิ่งแวดล้อม นอกจากนี้ยังมีการใช้ประโยชน์ในด้านต่าง ๆ เช่น การใช้เป็นไม้ประดับ การใช้ในทางสมุนไพร การใช้เป็นอาหาร และการใช้ในการศึกษาทางวิทยาศาสตร์และพฤกษศาสตร์.
A9149: 9148 | B9149: australe | C9149: syzygium-australe | D9149: Syzygium australe | E9149: {=IFERROR(INDEX(VRU!B$2:B$194,SMALL(IF(COUNTIF(Thailand!B$2:B$9145,VRU!B$2:B$194)=0,ROW(VRU!B$2:B$194)-ROW(VRU!B$2)+1),ROW(A5))),"")} -> คริสติน่า | F9149: Syzygium | G9149: =IFERROR(INDEX(VRU!D$2:D$194,MATCH(E9149,VRU!B$2:B$194,0)),"") -> MYRTACEAE | H9149: =IFERROR(INDEX(VRU!C$2:C$194,MATCH(E9149,VRU!B$2:B$194,0)),"") -> Syzygium australe (J.C.Wendl. ex Link) B.Hyland | I9149: คริสติน่า (ชื่อวิทยาศาสตร์: Syzygium australe) เป็นพืชในวงศ์ MYRTACEAE ซึ่งพบกระจายพันธุ์ในหลายภูมิภาคทั่วโลก โดยเฉพาะในเขตร้อนและกึ่งเขตร้อน มีลักษณะเป็นไม้ล้มลุก ไม้พุ่ม หรือไม้ยืนต้น ใบมีรูปร่างหลากหลาย เช่น รูปรี รูปไข่ หรือรูปหอก และมีดอกที่มีโครงสร้างเฉพาะตัว พืชชนิดนี้พบในแหล่งธรรมชาติ เช่น ป่าเขตร้อน ทุ่งหญ้า พื้นที่ชุ่มน้ำ หรือพื้นที่ชายฝั่ง มีบทบาทสำคัญในระบบนิเวศ เช่น เป็นแหล่งอาหารของสัตว์และช่วยรักษาสมดุลของสิ่งแวดล้อม นอกจากนี้ยังมีการใช้ประโยชน์ในด้านต่าง ๆ เช่น การใช้เป็นไม้ประดับ การใช้ในทางสมุนไพร การใช้เป็นอาหาร และการใช้ในการศึกษาทางวิทยาศาสตร์และพฤกษศาสตร์.
A9150: 9149 | B9150: serrulata | C9150: dolichandrone-serrulata | D9150: Dolichandrone serrulata | E9150: {=IFERROR(INDEX(VRU!B$2:B$194,SMALL(IF(COUNTIF(Thailand!B$2:B$9145,VRU!B$2:B$194)=0,ROW(VRU!B$2:B$194)-ROW(VRU!B$2)+1),ROW(A6))),"")} -> แคนา | F9150: Dolichandrone | G9150: =IFERROR(INDEX(VRU!D$2:D$194,MATCH(E9150,VRU!B$2:B$194,0)),"") -> BIGNONIACEAE | H9150: =IFERROR(INDEX(VRU!C$2:C$194,MATCH(E9150,VRU!B$2:B$194,0)),"") -> Dolichandrone serrulata (Wall. ex DC.) Seem. | I9150: แคนา (ชื่อวิทยาศาสตร์: Dolichandrone serrulata) เป็นพืชในวงศ์ BIGNONIACEAE ซึ่งพบกระจายพันธุ์ในหลายภูมิภาคทั่วโลก โดยเฉพาะในเขตร้อนและกึ่งเขตร้อน มีลักษณะเป็นไม้ล้มลุก ไม้พุ่ม หรือไม้ยืนต้น ใบมีรูปร่างหลากหลาย เช่น รูปรี รูปไข่ หรือรูปหอก และมีดอกที่มีโครงสร้างเฉพาะตัว พืชชนิดนี้พบในแหล่งธรรมชาติ เช่น ป่าเขตร้อน ทุ่งหญ้า พื้นที่ชุ่มน้ำ หรือพื้นที่ชายฝั่ง มีบทบาทสำคัญในระบบนิเวศ เช่น เป็นแหล่งอาหารของสัตว์และช่วยรักษาสมดุลของสิ่งแวดล้อม นอกจากนี้ยังมีการใช้ประโยชน์ในด้านต่าง ๆ เช่น การใช้เป็นไม้ประดับ การใช้ในทางสมุนไพร การใช้เป็นอาหาร และการใช้ในการศึกษาทางวิทยาศาสตร์และพฤกษศาสตร์.
A9151: 9150 | B9151: excelsa | C9151: rhapis-excelsa | D9151: Rhapis excelsa | E9151: {=IFERROR(INDEX(VRU!B$2:B$194,SMALL(IF(COUNTIF(Thailand!B$2:B$9145,VRU!B$2:B$194)=0,ROW(VRU!B$2:B$194)-ROW(VRU!B$2)+1),ROW(A7))),"")} -> จั๋งญี่ปุ่น | F9151: Rhapis | G9151: =IFERROR(INDEX(VRU!D$2:D$194,MATCH(E9151,VRU!B$2:B$194,0)),"") -> ARECACEAE | H9151: =IFERROR(INDEX(VRU!C$2:C$194,MATCH(E9151,VRU!B$2:B$194,0)),"") -> Rhapis excelsa (Thunb.) Henry | I9151: จั๋งญี่ปุ่น (ชื่อวิทยาศาสตร์: Rhapis excelsa) เป็นพืชในวงศ์ ARECACEAE ซึ่งพบกระจายพันธุ์ในหลายภูมิภาคทั่วโลก โดยเฉพาะในเขตร้อนและกึ่งเขตร้อน มีลักษณะเป็นไม้ล้มลุก ไม้พุ่ม หรือไม้ยืนต้น ใบมีรูปร่างหลากหลาย เช่น รูปรี รูปไข่ หรือรูปหอก และมีดอกที่มีโครงสร้างเฉพาะตัว พืชชนิดนี้พบในแหล่งธรรมชาติ เช่น ป่าเขตร้อน ทุ่งหญ้า พื้นที่ชุ่มน้ำ หรือพื้นที่ชายฝั่ง มีบทบาทสำคัญในระบบนิเวศ เช่น เป็นแหล่งอาหารของสัตว์และช่วยรักษาสมดุลของสิ่งแวดล้อม นอกจากนี้ยังมีการใช้ประโยชน์ในด้านต่าง ๆ เช่น การใช้เป็นไม้ประดับ การใช้ในทางสมุนไพร การใช้เป็นอาหาร และการใช้ในการศึกษาทางวิทยาศาสตร์และพฤกษศาสตร์.
A9152: 9151 | B9152: cochinchinensis | C9152: dracaena-cochinchinensis | D9152: Dracaena cochinchinensis | E9152: {=IFERROR(INDEX(VRU!B$2:B$194,SMALL(IF(COUNTIF(Thailand!B$2:B$9145,VRU!B$2:B$194)=0,ROW(VRU!B$2:B$194)-ROW(VRU!B$2)+1),ROW(A8))),"")} -> จันทน์ผา | F9152: Dracaena | G9152: =IFERROR(INDEX(VRU!D$2:D$194,MATCH(E9152,VRU!B$2:B$194,0)),"") -> ASPARAGACEAE | H9152: =IFERROR(INDEX(VRU!C$2:C$194,MATCH(E9152,VRU!B$2:B$194,0)),"") -> Dracaena cochinchinensis (Lour.) S. C. Chen | I9152: จันทน์ผา (ชื่อวิทยาศาสตร์: Dracaena cochinchinensis) เป็นพืชในวงศ์ ASPARAGACEAE ซึ่งพบกระจายพันธุ์ในหลายภูมิภาคทั่วโลก โดยเฉพาะในเขตร้อนและกึ่งเขตร้อน มีลักษณะเป็นไม้ล้มลุก ไม้พุ่ม หรือไม้ยืนต้น ใบมีรูปร่างหลากหลาย เช่น รูปรี รูปไข่ หรือรูปหอก และมีดอกที่มีโครงสร้างเฉพาะตัว พืชชนิดนี้พบในแหล่งธรรมชาติ เช่น ป่าเขตร้อน ทุ่งหญ้า พื้นที่ชุ่มน้ำ หรือพื้นที่ชายฝั่ง มีบทบาทสำคัญในระบบนิเวศ เช่น เป็นแหล่งอาหารของสัตว์และช่วยรักษาสมดุลของสิ่งแวดล้อม นอกจากนี้ยังมีการใช้ประโยชน์ในด้านต่าง ๆ เช่น การใช้เป็นไม้ประดับ การใช้ในทางสมุนไพร การใช้เป็นอาหาร และการใช้ในการศึกษาทางวิทยาศาสตร์และพฤกษศาสตร์.
A9153: 9152 | B9153: sp. | C9153: syzygium-sp. | D9153: Syzygium sp. | E9153: {=IFERROR(INDEX(VRU!B$2:B$194,SMALL(IF(COUNTIF(Thailand!B$2:B$9145,VRU!B$2:B$194)=0,ROW(VRU!B$2:B$194)-ROW(VRU!B$2)+1),ROW(A9))),"")} -> ชมพู่ | F9153: Syzygium | G9153: =IFERROR(INDEX(VRU!D$2:D$194,MATCH(E9153,VRU!B$2:B$194,0)),"") -> MYRTACEAE | H9153: =IFERROR(INDEX(VRU!C$2:C$194,MATCH(E9153,VRU!B$2:B$194,0)),"") -> Syzygium sp. | I9153: ชมพู่ (ชื่อวิทยาศาสตร์: Syzygium sp.) เป็นพืชในวงศ์ MYRTACEAE ซึ่งพบกระจายพันธุ์ในหลายภูมิภาคทั่วโลก โดยเฉพาะในเขตร้อนและกึ่งเขตร้อน มีลักษณะเป็นไม้ล้มลุก ไม้พุ่ม หรือไม้ยืนต้น ใบมีรูปร่างหลากหลาย เช่น รูปรี รูปไข่ หรือรูปหอก และมีดอกที่มีโครงสร้างเฉพาะตัว พืชชนิดนี้พบในแหล่งธรรมชาติ เช่น ป่าเขตร้อน ทุ่งหญ้า พื้นที่ชุ่มน้ำ หรือพื้นที่ชายฝั่ง มีบทบาทสำคัญในระบบนิเวศ เช่น เป็นแหล่งอาหารของสัตว์และช่วยรักษาสมดุลของสิ่งแวดล้อม นอกจากนี้ยังมีการใช้ประโยชน์ในด้านต่าง ๆ เช่น การใช้เป็นไม้ประดับ การใช้ในทางสมุนไพร การใช้เป็นอาหาร และการใช้ในการศึกษาทางวิทยาศาสตร์และพฤกษศาสตร์.
A9154: 9153 | B9154: malaccense | C9154: syzygium-malaccense | D9154: Syzygium malaccense | E9154: {=IFERROR(INDEX(VRU!B$2:B$194,SMALL(IF(COUNTIF(Thailand!B$2:B$9145,VRU!B$2:B$194)=0,ROW(VRU!B$2:B$194)-ROW(VRU!B$2)+1),ROW(A10))),"")} -> ชมพู่ม่าเหมี่ยว | F9154: Syzygium | G9154: =IFERROR(INDEX(VRU!D$2:D$194,MATCH(E9154,VRU!B$2:B$194,0)),"") -> MYRTACEAE | H9154: =IFERROR(INDEX(VRU!C$2:C$194,MATCH(E9154,VRU!B$2:B$194,0)),"") -> Syzygium malaccense (L.) Merr. & L. M. Perry | I9154: ชมพู่ม่าเหมี่ยว (ชื่อวิทยาศาสตร์: Syzygium malaccense) เป็นพืชในวงศ์ MYRTACEAE ซึ่งพบกระจายพันธุ์ในหลายภูมิภาคทั่วโลก โดยเฉพาะในเขตร้อนและกึ่งเขตร้อน มีลักษณะเป็นไม้ล้มลุก ไม้พุ่ม หรือไม้ยืนต้น ใบมีรูปร่างหลากหลาย เช่น รูปรี รูปไข่ หรือรูปหอก และมีดอกที่มีโครงสร้างเฉพาะตัว พืชชนิดนี้พบในแหล่งธรรมชาติ เช่น ป่าเขตร้อน ทุ่งหญ้า พื้นที่ชุ่มน้ำ หรือพื้นที่ชายฝั่ง มีบทบาทสำคัญในระบบนิเวศ เช่น เป็นแหล่งอาหารของสัตว์และช่วยรักษาสมดุลของสิ่งแวดล้อม นอกจากนี้ยังมีการใช้ประโยชน์ในด้านต่าง ๆ เช่น การใช้เป็นไม้ประดับ การใช้ในทางสมุนไพร การใช้เป็นอาหาร และการใช้ในการศึกษาทางวิทยาศาสตร์และพฤกษศาสตร์.
A9155: 9154 | B9155: glabra | C9155: vallaris-glabra | D9155: Vallaris glabra | E9155: {=IFERROR(INDEX(VRU!B$2:B$194,SMALL(IF(COUNTIF(Thailand!B$2:B$9145,VRU!B$2:B$194)=0,ROW(VRU!B$2:B$194)-ROW(VRU!B$2)+1),ROW(A11))),"")} -> ชมนาด | F9155: Vallaris | G9155: =IFERROR(INDEX(VRU!D$2:D$194,MATCH(E9155,VRU!B$2:B$194,0)),"") -> APOCYNACEAE | H9155: =IFERROR(INDEX(VRU!C$2:C$194,MATCH(E9155,VRU!B$2:B$194,0)),"") -> Vallaris glabra (L.) Kuntze | I9155: ชมนาด (ชื่อวิทยาศาสตร์: Vallaris glabra) เป็นพืชในวงศ์ APOCYNACEAE ซึ่งพบกระจายพันธุ์ในหลายภูมิภาคทั่วโลก โดยเฉพาะในเขตร้อนและกึ่งเขตร้อน มีลักษณะเป็นไม้ล้มลุก ไม้พุ่ม หรือไม้ยืนต้น ใบมีรูปร่างหลากหลาย เช่น รูปรี รูปไข่ หรือรูปหอก และมีดอกที่มีโครงสร้างเฉพาะตัว พืชชนิดนี้พบในแหล่งธรรมชาติ เช่น ป่าเขตร้อน ทุ่งหญ้า พื้นที่ชุ่มน้ำ หรือพื้นที่ชายฝั่ง มีบทบาทสำคัญในระบบนิเวศ เช่น เป็นแหล่งอาหารของสัตว์และช่วยรักษาสมดุลของสิ่งแวดล้อม นอกจากนี้ยังมีการใช้ประโยชน์ในด้านต่าง ๆ เช่น การใช้เป็นไม้ประดับ การใช้ในทางสมุนไพร การใช้เป็นอาหาร และการใช้ในการศึกษาทางวิทยาศาสตร์และพฤกษศาสตร์.
A9156: 9155 | B9156: glabra | C9156: malpighia-glabra | D9156: Malpighia glabra | E9156: {=IFERROR(INDEX(VRU!B$2:B$194,SMALL(IF(COUNTIF(Thailand!B$2:B$9145,VRU!B$2:B$194)=0,ROW(VRU!B$2:B$194)-ROW(VRU!B$2)+1),ROW(A12))),"")} -> เชอร์รี่ไทย | F9156: Malpighia | G9156: =IFERROR(INDEX(VRU!D$2:D$194,MATCH(E9156,VRU!B$2:B$194,0)),"") -> MALPIGHIACEAE | H9156: =IFERROR(INDEX(VRU!C$2:C$194,MATCH(E9156,VRU!B$2:B$194,0)),"") -> Malpighia glabra L. | I9156: เชอร์รี่ไทย (ชื่อวิทยาศาสตร์: Malpighia glabra) เป็นพืชในวงศ์ MALPIGHIACEAE ซึ่งพบกระจายพันธุ์ในหลายภูมิภาคทั่วโลก โดยเฉพาะในเขตร้อนและกึ่งเขตร้อน มีลักษณะเป็นไม้ล้มลุก ไม้พุ่ม หรือไม้ยืนต้น ใบมีรูปร่างหลากหลาย เช่น รูปรี รูปไข่ หรือรูปหอก และมีดอกที่มีโครงสร้างเฉพาะตัว พืชชนิดนี้พบในแหล่งธรรมชาติ เช่น ป่าเขตร้อน ทุ่งหญ้า พื้นที่ชุ่มน้ำ หรือพื้นที่ชายฝั่ง มีบทบาทสำคัญในระบบนิเวศ เช่น เป็นแหล่งอาหารของสัตว์และช่วยรักษาสมดุลของสิ่งแวดล้อม นอกจากนี้ยังมีการใช้ประโยชน์ในด้านต่าง ๆ เช่น การใช้เป็นไม้ประดับ การใช้ในทางสมุนไพร การใช้เป็นอาหาร และการใช้ในการศึกษาทางวิทยาศาสตร์และพฤกษศาสตร์.
... A9161: 9160 | B9161: benjamina | C9161: ficus-benjamina | D9161: Ficus benjamina | E9161: {=IFERROR(INDEX(VRU!B$2:B$194,SMALL(IF(COUNTIF(Thailand!B$2:B$9145,VRU!B$2:B$194)=0,ROW(VRU!B$2:B$194)-ROW(VRU!B$2)+1),ROW(A17))),"")} -> ไทรย้อยใบแหลม | F9161: Ficus | G9161: =IFERROR(INDEX(VRU!D$2:D$194,MATCH(E9161,VRU!B$2:B$194,0)),"") -> MORACEAE | H9161: =IFERROR(INDEX(VRU!C$2:C$194,MATCH(E9161,VRU!B$2:B$194,0)),"") -> Ficus benjamina L. | I9161: ไทรย้อยใบแหลม (ชื่อวิทยาศาสตร์: Ficus benjamina) เป็นพืชในวงศ์ MORACEAE ซึ่งพบกระจายพันธุ์ในหลายภูมิภาคทั่วโลก โดยเฉพาะในเขตร้อนและกึ่งเขตร้อน มีลักษณะเป็นไม้ล้มลุก ไม้พุ่ม หรือไม้ยืนต้น ใบมีรูปร่างหลากหลาย เช่น รูปรี รูปไข่ หรือรูปหอก และมีดอกที่มีโครงสร้างเฉพาะตัว พืชชนิดนี้พบในแหล่งธรรมชาติ เช่น ป่าเขตร้อน ทุ่งหญ้า พื้นที่ชุ่มน้ำ หรือพื้นที่ชายฝั่ง มีบทบาทสำคัญในระบบนิเวศ เช่น เป็นแหล่งอาหารของสัตว์และช่วยรักษาสมดุลของสิ่งแวดล้อม นอกจากนี้ยังมีการใช้ประโยชน์ในด้านต่าง ๆ เช่น การใช้เป็นไม้ประดับ การใช้ในทางสมุนไพร การใช้เป็นอาหาร และการใช้ในการศึกษาทางวิทยาศาสตร์และพฤกษศาสตร์.
A9162: 9161 | B9162: annulata | C9162: ficus-annulata | D9162: Banyan Tree | E9162: {=IFERROR(INDEX(VRU!B$2:B$194,SMALL(IF(COUNTIF(Thailand!B$2:B$9145,VRU!B$2:B$194)=0,ROW(VRU!B$2:B$194)-ROW(VRU!B$2)+1),ROW(A18))),"")} -> ไทรเกาหลี | F9162: Ficus | G9162: =IFERROR(INDEX(VRU!D$2:D$194,MATCH(E9162,VRU!B$2:B$194,0)),"") -> MORACEAE | H9162: Ficus annulata Blume | I9162: ไทรเกาหลี (ชื่อวิทยาศาสตร์: Ficus annulata) เป็นพืชในวงศ์ Moraceae ซึ่งพบกระจายพันธุ์ในหลายภูมิภาคทั่วโลก โดยเฉพาะในเขตร้อนและกึ่งเขตร้อน มีลักษณะเป็นไม้ยืนต้นหรือไม้พุ่ม ทรงพุ่มแน่น ใบเดี่ยวรูปรีหรือรูปไข่ สีเขียวเข้ม และมีลำต้นสีน้ำตาลอมเทา พืชชนิดนี้พบในแหล่งธรรมชาติ เช่น ป่าเขตร้อน และนิยมปลูกเป็นไม้ประดับหรือใช้ทำรั้วเนื่องจากสามารถตัดแต่งรูปทรงได้ง่าย มีบทบาทสำคัญในระบบนิเวศ เช่น เป็นแหล่งที่อยู่อาศัยของสัตว์และช่วยรักษาสมดุลของสิ่งแวดล้อม นอกจากนี้ยังมีการใช้ประโยชน์ในด้านต่าง ๆ เช่น การใช้เป็นไม้ประดับ การจัดภูมิทัศน์ และการใช้ในการศึกษาทางพฤกษศาสตร์และวิทยาศาสตร์.
A9163: 9162 | B9163: psittacorum | C9163: heliconia-psittacorum | D9163: Heliconia psittacorum | E9163: {=IFERROR(INDEX(VRU!B$2:B$194,SMALL(IF(COUNTIF(Thailand!B$2:B$9145,VRU!B$2:B$194)=0,ROW(VRU!B$2:B$194)-ROW(VRU!B$2)+1),ROW(A19))),"")} -> ธรรมรักษา | F9163: Heliconia | G9163: =IFERROR(INDEX(VRU!D$2:D$194,MATCH(E9163,VRU!B$2:B$194,0)),"") -> HELICONIACEAE | H9163: =IFERROR(INDEX(VRU!C$2:C$194,MATCH(E9163,VRU!B$2:B$194,0)),"") -> Heliconia psittacorum L. f. | I9163: ธรรมรักษา (ชื่อวิทยาศาสตร์: Heliconia psittacorum) เป็นพืชในวงศ์ HELICONIACEAE ซึ่งพบกระจายพันธุ์ในหลายภูมิภาคทั่วโลก โดยเฉพาะในเขตร้อนและกึ่งเขตร้อน มีลักษณะเป็นไม้ล้มลุก ไม้พุ่ม หรือไม้ยืนต้น ใบมีรูปร่างหลากหลาย เช่น รูปรี รูปไข่ หรือรูปหอก และมีดอกที่มีโครงสร้างเฉพาะตัว พืชชนิดนี้พบในแหล่งธรรมชาติ เช่น ป่าเขตร้อน ทุ่งหญ้า พื้นที่ชุ่มน้ำ หรือพื้นที่ชายฝั่ง มีบทบาทสำคัญในระบบนิเวศ เช่น เป็นแหล่งอาหารของสัตว์และช่วยรักษาสมดุลของสิ่งแวดล้อม นอกจากนี้ยังมีการใช้ประโยชน์ในด้านต่าง ๆ เช่น การใช้เป็นไม้ประดับ การใช้ในทางสมุนไพร การใช้เป็นอาหาร และการใช้ในการศึกษาทางวิทยาศาสตร์และพฤกษศาสตร์.
A9164: 9163 | B9164: pictum | C9164: graptophyllum-pictum | D9164: Graptophyllum pictum | E9164: {=IFERROR(INDEX(VRU!B$2:B$194,SMALL(IF(COUNTIF(Thailand!B$2:B$9145,VRU!B$2:B$194)=0,ROW(VRU!B$2:B$194)-ROW(VRU!B$2)+1),ROW(A20))),"")} -> ใบเงิน ใบทอง | F9164: Graptophyllum | G9164: =IFERROR(INDEX(VRU!D$2:D$194,MATCH(E9164,VRU!B$2:B$194,0)),"") -> ACANTHACEAE | H9164: =IFERROR(INDEX(VRU!C$2:C$194,MATCH(E9164,VRU!B$2:B$194,0)),"") -> Graptophyllum pictum (L.) Griff. | I9164: ใบเงิน ใบทอง (ชื่อวิทยาศาสตร์: Graptophyllum pictum) เป็นพืชในวงศ์ ACANTHACEAE ซึ่งพบกระจายพันธุ์ในหลายภูมิภาคทั่วโลก โดยเฉพาะในเขตร้อนและกึ่งเขตร้อน มีลักษณะเป็นไม้ล้มลุก ไม้พุ่ม หรือไม้ยืนต้น ใบมีรูปร่างหลากหลาย เช่น รูปรี รูปไข่ หรือรูปหอก และมีดอกที่มีโครงสร้างเฉพาะตัว พืชชนิดนี้พบในแหล่งธรรมชาติ เช่น ป่าเขตร้อน ทุ่งหญ้า พื้นที่ชุ่มน้ำ หรือพื้นที่ชายฝั่ง มีบทบาทสำคัญในระบบนิเวศ เช่น เป็นแหล่งอาหารของสัตว์และช่วยรักษาสมดุลของสิ่งแวดล้อม นอกจากนี้ยังมีการใช้ประโยชน์ในด้านต่าง ๆ เช่น การใช้เป็นไม้ประดับ การใช้ในทางสมุนไพร การใช้เป็นอาหาร และการใช้ในการศึกษาทางวิทยาศาสตร์และพฤกษศาสตร์.
A9165: 9164 | B9165: hainanensis | C9165: radermachera-hainanensis | D9165: Radermachera hainanensis | E9165: {=IFERROR(INDEX(VRU!B$2:B$194,SMALL(IF(COUNTIF(Thailand!B$2:B$9145,VRU!B$2:B$194)=0,ROW(VRU!B$2:B$194)-ROW(VRU!B$2)+1),ROW(A21))),"")} -> ปีปทอง | F9165: Radermachera | G9165: =IFERROR(INDEX(VRU!D$2:D$194,MATCH(E9165,VRU!B$2:B$194,0)),"") -> BIGNONIACEAE | H9165: =IFERROR(INDEX(VRU!C$2:C$194,MATCH(E9165,VRU!B$2:B$194,0)),"") -> Radermachera hainanensis Merr. | I9165: ปีปทอง (ชื่อวิทยาศาสตร์: Radermachera hainanensis) เป็นพืชในวงศ์ BIGNONIACEAE ซึ่งพบกระจายพันธุ์ในหลายภูมิภาคทั่วโลก โดยเฉพาะในเขตร้อนและกึ่งเขตร้อน มีลักษณะเป็นไม้ล้มลุก ไม้พุ่ม หรือไม้ยืนต้น ใบมีรูปร่างหลากหลาย เช่น รูปรี รูปไข่ หรือรูปหอก และมีดอกที่มีโครงสร้างเฉพาะตัว พืชชนิดนี้พบในแหล่งธรรมชาติ เช่น ป่าเขตร้อน ทุ่งหญ้า พื้นที่ชุ่มน้ำ หรือพื้นที่ชายฝั่ง มีบทบาทสำคัญในระบบนิเวศ เช่น เป็นแหล่งอาหารของสัตว์และช่วยรักษาสมดุลของสิ่งแวดล้อม นอกจากนี้ยังมีการใช้ประโยชน์ในด้านต่าง ๆ เช่น การใช้เป็นไม้ประดับ การใช้ในทางสมุนไพร การใช้เป็นอาหาร และการใช้ในการศึกษาทางวิทยาศาสตร์และพฤกษศาสตร์.
A9166: 9165 | B9166: sp. | C9166: bambusa-sp. | D9166: Bambusa sp. | E9166: {=IFERROR(INDEX(VRU!B$2:B$194,SMALL(IF(COUNTIF(Thailand!B$2:B$9145,VRU!B$2:B$194)=0,ROW(VRU!B$2:B$194)-ROW(VRU!B$2)+1),ROW(A22))),"")} -> ไผ่ | F9166: Bambusa | G9166: =IFERROR(INDEX(VRU!D$2:D$194,MATCH(E9166,VRU!B$2:B$194,0)),"") -> POACEAE | H9166: =IFERROR(INDEX(VRU!C$2:C$194,MATCH(E9166,VRU!B$2:B$194,0)),"") -> Bambusa sp. | I9166: ไผ่ (ชื่อวิทยาศาสตร์: Bambusa sp.) เป็นพืชในวงศ์ POACEAE ซึ่งพบกระจายพันธุ์ในหลายภูมิภาคทั่วโลก โดยเฉพาะในเขตร้อนและกึ่งเขตร้อน มีลักษณะเป็นไม้ล้มลุก ไม้พุ่ม หรือไม้ยืนต้น ใบมีรูปร่างหลากหลาย เช่น รูปรี รูปไข่ หรือรูปหอก และมีดอกที่มีโครงสร้างเฉพาะตัว พืชชนิดนี้พบในแหล่งธรรมชาติ เช่น ป่าเขตร้อน ทุ่งหญ้า พื้นที่ชุ่มน้ำ หรือพื้นที่ชายฝั่ง มีบทบาทสำคัญในระบบนิเวศ เช่น เป็นแหล่งอาหารของสัตว์และช่วยรักษาสมดุลของสิ่งแวดล้อม นอกจากนี้ยังมีการใช้ประโยชน์ในด้านต่าง ๆ เช่น การใช้เป็นไม้ประดับ การใช้ในทางสมุนไพร การใช้เป็นอาหาร และการใช้ในการศึกษาทางวิทยาศาสตร์และพฤกษศาสตร์.
A9167: 9166 | B9167: carinata | C9167: gardenia-carinata | D9167: Gardenia carinata | E9167: {=IFERROR(INDEX(VRU!B$2:B$194,SMALL(IF(COUNTIF(Thailand!B$2:B$9145,VRU!B$2:B$194)=0,ROW(VRU!B$2:B$194)-ROW(VRU!B$2)+1),ROW(A23))),"")} -> พุดน้ำบุศย์ | F9167: Gardenia | G9167: =IFERROR(INDEX(VRU!D$2:D$194,MATCH(E9167,VRU!B$2:B$194,0)),"") -> RUBIACEAE | H9167: =IFERROR(INDEX(VRU!C$2:C$194,MATCH(E9167,VRU!B$2:B$194,0)),"") -> Gardenia carinata Wall. ex Roxb. | I9167: พุดน้ำบุศย์ (ชื่อวิทยาศาสตร์: Gardenia carinata) เป็นพืชในวงศ์ RUBIACEAE ซึ่งพบกระจายพันธุ์ในหลายภูมิภาคทั่วโลก โดยเฉพาะในเขตร้อนและกึ่งเขตร้อน มีลักษณะเป็นไม้ล้มลุก ไม้พุ่ม หรือไม้ยืนต้น ใบมีรูปร่างหลากหลาย เช่น รูปรี รูปไข่ หรือรูปหอก และมีดอกที่มีโครงสร้างเฉพาะตัว พืชชนิดนี้พบในแหล่งธรรมชาติ เช่น ป่าเขตร้อน ทุ่งหญ้า พื้นที่ชุ่มน้ำ หรือพื้นที่ชายฝั่ง มีบทบาทสำคัญในระบบนิเวศ เช่น เป็นแหล่งอาหารของสัตว์และช่วยรักษาสมดุลของสิ่งแวดล้อม นอกจากนี้ยังมีการใช้ประโยชน์ในด้านต่าง ๆ เช่น การใช้เป็นไม้ประดับ การใช้ในทางสมุนไพร การใช้เป็นอาหาร และการใช้ในการศึกษาทางวิทยาศาสตร์และพฤกษศาสตร์.
A9168: 9167 | B9168: grandiflorum | C9168: jasminum-grandiflorum | D9168: Jasminum grandiflorum | E9168: {=IFERROR(INDEX(VRU!B$2:B$194,SMALL(IF(COUNTIF(Thailand!B$2:B$9145,VRU!B$2:B$194)=0,ROW(VRU!B$2:B$194)-ROW(VRU!B$2)+1),ROW(A24))),"")} -> พุทธชาดก้านแดง | F9168: Jasminum | G9168: =IFERROR(INDEX(VRU!D$2:D$194,MATCH(E9168,VRU!B$2:B$194,0)),"") -> OLEACEAE | H9168: =IFERROR(INDEX(VRU!C$2:C$194,MATCH(E9168,VRU!B$2:B$194,0)),"") -> Jasminum grandiflorum L. | I9168: พุทธชาดก้านแดง (ชื่อวิทยาศาสตร์: Jasminum grandiflorum) เป็นพืชในวงศ์ OLEACEAE ซึ่งพบกระจายพันธุ์ในหลายภูมิภาคทั่วโลก โดยเฉพาะในเขตร้อนและกึ่งเขตร้อน มีลักษณะเป็นไม้ล้มลุก ไม้พุ่ม หรือไม้ยืนต้น ใบมีรูปร่างหลากหลาย เช่น รูปรี รูปไข่ หรือรูปหอก และมีดอกที่มีโครงสร้างเฉพาะตัว พืชชนิดนี้พบในแหล่งธรรมชาติ เช่น ป่าเขตร้อน ทุ่งหญ้า พื้นที่ชุ่มน้ำ หรือพื้นที่ชายฝั่ง มีบทบาทสำคัญในระบบนิเวศ เช่น เป็นแหล่งอาหารของสัตว์และช่วยรักษาสมดุลของสิ่งแวดล้อม นอกจากนี้ยังมีการใช้ประโยชน์ในด้านต่าง ๆ เช่น การใช้เป็นไม้ประดับ การใช้ในทางสมุนไพร การใช้เป็นอาหาร และการใช้ในการศึกษาทางวิทยาศาสตร์และพฤกษศาสตร์.
A9169: 9168 | B9169: jasminoides | C9169: gardenia-jasminoides | D9169: Gardenia jasminoides | E9169: {=IFERROR(INDEX(VRU!B$2:B$194,SMALL(IF(COUNTIF(Thailand!B$2:B$9145,VRU!B$2:B$194)=0,ROW(VRU!B$2:B$194)-ROW(VRU!B$2)+1),ROW(A25))),"")} -> พุดศุภโชค (พุดซ้อน) | F9169: Gardenia | G9169: =IFERROR(INDEX(VRU!D$2:D$194,MATCH(E9169,VRU!B$2:B$194,0)),"") -> RUBIACEAE | H9169: =IFERROR(INDEX(VRU!C$2:C$194,MATCH(E9169,VRU!B$2:B$194,0)),"") -> Gardenia jasminoides J. Ellis | I9169: พุดศุภโชค (พุดซ้อน) (ชื่อวิทยาศาสตร์: Gardenia jasminoides) เป็นพืชในวงศ์ RUBIACEAE ซึ่งพบกระจายพันธุ์ในหลายภูมิภาคทั่วโลก โดยเฉพาะในเขตร้อนและกึ่งเขตร้อน มีลักษณะเป็นไม้ล้มลุก ไม้พุ่ม หรือไม้ยืนต้น ใบมีรูปร่างหลากหลาย เช่น รูปรี รูปไข่ หรือรูปหอก และมีดอกที่มีโครงสร้างเฉพาะตัว พืชชนิดนี้พบในแหล่งธรรมชาติ เช่น ป่าเขตร้อน ทุ่งหญ้า พื้นที่ชุ่มน้ำ หรือพื้นที่ชายฝั่ง มีบทบาทสำคัญในระบบนิเวศ เช่น เป็นแหล่งอาหารของสัตว์และช่วยรักษาสมดุลของสิ่งแวดล้อม นอกจากนี้ยังมีการใช้ประโยชน์ในด้านต่าง ๆ เช่น การใช้เป็นไม้ประดับ การใช้ในทางสมุนไพร การใช้เป็นอาหาร และการใช้ในการศึกษาทางวิทยาศาสตร์และพฤกษศาสตร์.
A9170: 9169 | B9170: oppositifolia | C9170: bouea-oppositifolia | D9170: Bouea oppositifolia | E9170: {=IFERROR(INDEX(VRU!B$2:B$194,SMALL(IF(COUNTIF(Thailand!B$2:B$9145,VRU!B$2:B$194)=0,ROW(VRU!B$2:B$194)-ROW(VRU!B$2)+1),ROW(A26))),"")} -> มะยงชิด | F9170: Bouea | G9170: =IFERROR(INDEX(VRU!D$2:D$194,MATCH(E9170,VRU!B$2:B$194,0)),"") -> ANACARDIACEAE | H9170: =IFERROR(INDEX(VRU!C$2:C$194,MATCH(E9170,VRU!B$2:B$194,0)),"") -> Bouea oppositifolia (Roxb.) Meisn. | I9170: มะยงชิด (ชื่อวิทยาศาสตร์: Bouea oppositifolia) เป็นพืชในวงศ์ ANACARDIACEAE ซึ่งพบกระจายพันธุ์ในหลายภูมิภาคทั่วโลก โดยเฉพาะในเขตร้อนและกึ่งเขตร้อน มีลักษณะเป็นไม้ล้มลุก ไม้พุ่ม หรือไม้ยืนต้น ใบมีรูปร่างหลากหลาย เช่น รูปรี รูปไข่ หรือรูปหอก และมีดอกที่มีโครงสร้างเฉพาะตัว พืชชนิดนี้พบในแหล่งธรรมชาติ เช่น ป่าเขตร้อน ทุ่งหญ้า พื้นที่ชุ่มน้ำ หรือพื้นที่ชายฝั่ง มีบทบาทสำคัญในระบบนิเวศ เช่น เป็นแหล่งอาหารของสัตว์และช่วยรักษาสมดุลของสิ่งแวดล้อม นอกจากนี้ยังมีการใช้ประโยชน์ในด้านต่าง ๆ เช่น การใช้เป็นไม้ประดับ การใช้ในทางสมุนไพร การใช้เป็นอาหาร และการใช้ในการศึกษาทางวิทยาศาสตร์และพฤกษศาสตร์.
A9171: 9170 | B9171: thomasiana | C9171: ochna-thomasiana | D9171: Ochna thomasiana | E9171: {=IFERROR(INDEX(VRU!B$2:B$194,SMALL(IF(COUNTIF(Thailand!B$2:B$9145,VRU!B$2:B$194)=0,ROW(VRU!B$2:B$194)-ROW(VRU!B$2)+1),ROW(A27))),"")} -> มิกกี้เมาส์ | F9171: Ochna | G9171: =IFERROR(INDEX(VRU!D$2:D$194,MATCH(E9171,VRU!B$2:B$194,0)),"") -> OCHNACEAE | H9171: =IFERROR(INDEX(VRU!C$2:C$194,MATCH(E9171,VRU!B$2:B$194,0)),"") -> Ochna thomasiana Engl. & Gilg | I9171: มิกกี้เมาส์ (ชื่อวิทยาศาสตร์: Ochna thomasiana) เป็นพืชในวงศ์ OCHNACEAE ซึ่งพบกระจายพันธุ์ในหลายภูมิภาคทั่วโลก โดยเฉพาะในเขตร้อนและกึ่งเขตร้อน มีลักษณะเป็นไม้ล้มลุก ไม้พุ่ม หรือไม้ยืนต้น ใบมีรูปร่างหลากหลาย เช่น รูปรี รูปไข่ หรือรูปหอก และมีดอกที่มีโครงสร้างเฉพาะตัว พืชชนิดนี้พบในแหล่งธรรมชาติ เช่น ป่าเขตร้อน ทุ่งหญ้า พื้นที่ชุ่มน้ำ หรือพื้นที่ชายฝั่ง มีบทบาทสำคัญในระบบนิเวศ เช่น เป็นแหล่งอาหารของสัตว์และช่วยรักษาสมดุลของสิ่งแวดล้อม นอกจากนี้ยังมีการใช้ประโยชน์ในด้านต่าง ๆ เช่น การใช้เป็นไม้ประดับ การใช้ในทางสมุนไพร การใช้เป็นอาหาร และการใช้ในการศึกษาทางวิทยาศาสตร์และพฤกษศาสตร์.
A9172: 9171 | B9172: campechiana | C9172: pouteria-campechiana | D9172: Pouteria campechiana | E9172: {=IFERROR(INDEX(VRU!B$2:B$194,SMALL(IF(COUNTIF(Thailand!B$2:B$9145,VRU!B$2:B$194)=0,ROW(VRU!B$2:B$194)-ROW(VRU!B$2)+1),ROW(A28))),"")} -> ละมุดเขมร | F9172: Pouteria | G9172: =IFERROR(INDEX(VRU!D$2:D$194,MATCH(E9172,VRU!B$2:B$194,0)),"") -> SAPOTACEAE | H9172: =IFERROR(INDEX(VRU!C$2:C$194,MATCH(E9172,VRU!B$2:B$194,0)),"") -> Pouteria campechiana (Kunth) Baehni | I9172: ละมุดเขมร (ชื่อวิทยาศาสตร์: Pouteria campechiana) เป็นพืชในวงศ์ SAPOTACEAE ซึ่งพบกระจายพันธุ์ในหลายภูมิภาคทั่วโลก โดยเฉพาะในเขตร้อนและกึ่งเขตร้อน มีลักษณะเป็นไม้ล้มลุก ไม้พุ่ม หรือไม้ยืนต้น ใบมีรูปร่างหลากหลาย เช่น รูปรี รูปไข่ หรือรูปหอก และมีดอกที่มีโครงสร้างเฉพาะตัว พืชชนิดนี้พบในแหล่งธรรมชาติ เช่น ป่าเขตร้อน ทุ่งหญ้า พื้นที่ชุ่มน้ำ หรือพื้นที่ชายฝั่ง มีบทบาทสำคัญในระบบนิเวศ เช่น เป็นแหล่งอาหารของสัตว์และช่วยรักษาสมดุลของสิ่งแวดล้อม นอกจากนี้ยังมีการใช้ประโยชน์ในด้านต่าง ๆ เช่น การใช้เป็นไม้ประดับ การใช้ในทางสมุนไพร การใช้เป็นอาหาร และการใช้ในการศึกษาทางวิทยาศาสตร์และพฤกษศาสตร์.
A9173: 9172 | B9173: rubra | C9173: plumeria-rubra | D9173: Plumeria rubra | E9173: {=IFERROR(INDEX(VRU!B$2:B$194,SMALL(IF(COUNTIF(Thailand!B$2:B$9145,VRU!B$2:B$194)=0,ROW(VRU!B$2:B$194)-ROW(VRU!B$2)+1),ROW(A29))),"")} -> ลั่นทมแดง | F9173: Plumeria | G9173: =IFERROR(INDEX(VRU!D$2:D$194,MATCH(E9173,VRU!B$2:B$194,0)),"") -> APOCYNACEAE | H9173: =IFERROR(INDEX(VRU!C$2:C$194,MATCH(E9173,VRU!B$2:B$194,0)),"") -> Plumeria rubra L. | I9173: ลั่นทมแดง (ชื่อวิทยาศาสตร์: Plumeria rubra) เป็นพืชในวงศ์ APOCYNACEAE ซึ่งพบกระจายพันธุ์ในหลายภูมิภาคทั่วโลก โดยเฉพาะในเขตร้อนและกึ่งเขตร้อน มีลักษณะเป็นไม้ล้มลุก ไม้พุ่ม หรือไม้ยืนต้น ใบมีรูปร่างหลากหลาย เช่น รูปรี รูปไข่ หรือรูปหอก และมีดอกที่มีโครงสร้างเฉพาะตัว พืชชนิดนี้พบในแหล่งธรรมชาติ เช่น ป่าเขตร้อน ทุ่งหญ้า พื้นที่ชุ่มน้ำ หรือพื้นที่ชายฝั่ง มีบทบาทสำคัญในระบบนิเวศ เช่น เป็นแหล่งอาหารของสัตว์และช่วยรักษาสมดุลของสิ่งแวดล้อม นอกจากนี้ยังมีการใช้ประโยชน์ในด้านต่าง ๆ เช่น การใช้เป็นไม้ประดับ การใช้ในทางสมุนไพร การใช้เป็นอาหาร และการใช้ในการศึกษาทางวิทยาศาสตร์และพฤกษศาสตร์.
A9174: 9173 | B9174: cochinchinensis | C9174: excoecaria-cochinchinensis | D9174: Excoecaria cochinchinensis | E9174: {=IFERROR(INDEX(VRU!B$2:B$194,SMALL(IF(COUNTIF(Thailand!B$2:B$9145,VRU!B$2:B$194)=0,ROW(VRU!B$2:B$194)-ROW(VRU!B$2)+1),ROW(A30))),"")} -> ลิ้นกระบือ | F9174: Excoecaria | G9174: =IFERROR(INDEX(VRU!D$2:D$194,MATCH(E9174,VRU!B$2:B$194,0)),"") -> EUPHORBIACEAE | H9174: =IFERROR(INDEX(VRU!C$2:C$194,MATCH(E9174,VRU!B$2:B$194,0)),"") -> Excoecaria cochinchinensis Lour. var. cochinchinensis | I9174: ลิ้นกระบือ (ชื่อวิทยาศาสตร์: Excoecaria cochinchinensis) เป็นพืชในวงศ์ EUPHORBIACEAE ซึ่งพบกระจายพันธุ์ในหลายภูมิภาคทั่วโลก โดยเฉพาะในเขตร้อนและกึ่งเขตร้อน มีลักษณะเป็นไม้ล้มลุก ไม้พุ่ม หรือไม้ยืนต้น ใบมีรูปร่างหลากหลาย เช่น รูปรี รูปไข่ หรือรูปหอก และมีดอกที่มีโครงสร้างเฉพาะตัว พืชชนิดนี้พบในแหล่งธรรมชาติ เช่น ป่าเขตร้อน ทุ่งหญ้า พื้นที่ชุ่มน้ำ หรือพื้นที่ชายฝั่ง มีบทบาทสำคัญในระบบนิเวศ เช่น เป็นแหล่งอาหารของสัตว์และช่วยรักษาสมดุลของสิ่งแวดล้อม นอกจากนี้ยังมีการใช้ประโยชน์ในด้านต่าง ๆ เช่น การใช้เป็นไม้ประดับ การใช้ในทางสมุนไพร การใช้เป็นอาหาร และการใช้ในการศึกษาทางวิทยาศาสตร์และพฤกษศาสตร์.
...
